package test.assertk

import assertk.assert
import assertk.assertions.isEqualTo
import assertk.assertions.isNegative
import assertk.assertions.isPositive
import assertk.assertions.message
import assertk.assertions.support.show
import assertk.thrownExpectedError
import kotlin.test.Test
import kotlin.test.assertEquals
import kotlin.test.assertFails

class AssertBlockTest {
    val returnSubject = assert { 1 + 1 }
    val errorSubject = assert { throw Exception("test") }

    //region returnedValue
    @Test fun returnedValue_successful_assertion_passes() {
        returnSubject.returnedValue { isEqualTo(2) }
    }

    @Test fun returnedValue_unsuccessful_assertion_fails() {
        val error = assertFails {
            returnSubject.returnedValue {
                isNegative()
            }
        }
        assertEquals("expected to be negative but was:<2>", error.message)
    }

    @Test fun returnedValue_exception_in_block_fails() {
        val error = assertFails {
            errorSubject.returnedValue {
                isPositive()
            }
        }
        assertEquals("expected value but threw:${show(Exception("test"))}", error.message)
    }
    //endregion

    //region thrownError
    @Test fun thrownError_successful_assertion_passes() {
        errorSubject.thrownError {
            message().isEqualTo("test")
        }
    }

    @Test fun thrownError_unsuccessful_assertion_fails() {
        val error = assertFails {
            errorSubject.thrownError {
                message().isEqualTo("wrong")
            }
        }
        assertEquals(
            "expected [message]:<\"[wrong]\"> but was:<\"[test]\"> ${show(Exception("test"), "()")}",
            error.message
        )
    }

    @Test fun thrownError_no_exception_in_block_fails() {
        val error = assertFails {
            returnSubject.thrownError {
                message().isEqualTo("error")
            }
        }
        assertEquals("expected exception but was:<2>", error.message)
    }
    //endregion

    //region doesNotThrowAnyException
    @Test fun doesNotThrowAnyException_no_exception_passes() {
        returnSubject.doesNotThrowAnyException()
    }

    @Test fun doesNotThrowAnyException_exception_fails() {
        val error = assertFails {
            errorSubject.doesNotThrowAnyException()
        }
        assertEquals(
            "expected to not throw an exception but threw:<${exceptionPackageName}Exception: test>",
            error.message
        )
    }
    //endregion

    //region throwsExpectedException
    @Test
    fun throwsExpectedException_passes() {
        assert { throw IllegalStateException("you illegal!") }
                .thrownExpectedError<IllegalStateException> {
                    message().isEqualTo("you illegal!")
                }
    }

    @Test
    fun throwsExpectedException_fails() {
        val error = assertFails {
            assert { throw IllegalStateException("you illegal!") }
                    .thrownExpectedError<IllegalArgumentException> {
                        message().isEqualTo("you illegal!")
                    }
        }
        assertEquals(
                "expected Throwable to be of type <class ${exceptionPackageName}IllegalArgumentException> but actual was <class ${exceptionPackageName}IllegalStateException>",
                error.message
        )
    }
    //endregion
}